<?xml version="1.0" encoding="utf-8"?>
<robot xmlns:xacro="http://www.ros.org/wiki/xacro" name="spider_robot">


	<gazebo>
	  <plugin name="gazebo_ros_control" filename="libgazebo_ros_control.so">
		<robotNamespace>/spider_robot</robotNamespace>
	  </plugin>

	</gazebo>

	<gazebo reference="camera_link">
		<sensor type="camera" name="camera1">
			<update_rate>30.0</update_rate>
			<camera name="head">
				<horizontal_fov>1.3962634</horizontal_fov>
				<image>
					<width>800</width>
					<height>800</height>
					<format>R8G8B8</format>
				</image>
				<clip>
					<near>0.02</near>
					<far>300</far>
				</clip>

			</camera>


			<plugin name="camera_controller" filename="libgazebo_ros_camera.so">
				<alwaysOn>true</alwaysOn>
				<updateRate>0.0</updateRate>
				<cameraName>spider_robot/camera1</cameraName>
				<imageTopicName>image_raw</imageTopicName>
				<cameraInfoTopicName>camera_info</cameraInfoTopicName>
				<frameName>camera_link</frameName>
				<hackBaseline>0.07</hackBaseline>
				<distortionK1>0.0</distortionK1>
				<distortionK2>0.0</distortionK2>
				<distortionK3>0.0</distortionK3>
				<distortionT1>0.0</distortionT1>
				<distortionT2>0.0</distortionT2>
			</plugin>
		</sensor>

	</gazebo>


	<xacro:macro name="transm" params="t_name joint m_name">
		<transmission name="${t_name}">
		  <type>transmission_interface/SimpleTransmission</type>
		  <joint name="${joint}">
			<hardwareInterface>EffortJointInterface</hardwareInterface>
		  </joint>
		  <actuator name="${m_name}">
			<mechanicalReduction>1</mechanicalReduction>
			<hardwareInterface>EffortJointInterface</hardwareInterface>
		  </actuator>
		</transmission>
	</xacro:macro>



    <link name ="world"/>

    <link name="base_link">
		<visual>
		    <origin xyz="0 0 5"/>

			<geometry>
				<box size="2 2 2"/>
			</geometry>
			<material name="Cyan">
				<color rgba="0 1 1 0.5"/>
			</material>
		</visual>
		<inertial>
      		<mass value="10"/>
      		<inertia ixx="0.4" ixy="0.0" ixz="0.0" iyy="0.4" iyz="0.0" izz="0.2"/>
    	</inertial>

	</link>

    <joint name="world_to_base" type="fixed">
		<parent link = "world"/>
		<child link = "base_link"/>
	</joint>

	<xacro:macro name="link_cylinder_collision" params="name radius length">
		<link name="${name}">
		<visual>

			<geometry>
				<cylinder radius="${radius}" length="${length}"/>
			</geometry>

		</visual>
		<inertial>
      		<mass value="10"/>
      		<inertia ixx="0.4" ixy="0.0" ixz="0.0" iyy="0.4" iyz="0.0" izz="0.2"/>
    	</inertial>
<!--		<collision>-->
<!--      		<geometry>-->
<!--        		<box size="0.3 0.25 0.6"/>-->
<!--      		</geometry>-->
<!--    	</collision>-->
		</link>
	</xacro:macro>

	<xacro:macro name="link_cylinder" params="name radius length">
		<link name="${name}">
		<visual>

			<geometry>
				<cylinder radius="${radius}" length="${length}"/>
			</geometry>

		</visual>
		<inertial>
      		<mass value="10"/>
      		<inertia ixx="0.4" ixy="0.0" ixz="0.0" iyy="0.4" iyz="0.0" izz="0.2"/>
    	</inertial>

		</link>
	</xacro:macro>


	<xacro:macro name="revolute_joint" params="name parent child coords angles axis lower upper">
        <joint name="${name}" type="revolute">
            <limit effort="100"  velocity="3" lower="${lower}" upper="${upper}"/>
			<axis xyz="${axis}"/>
			<parent link="${parent}"/>
            <child link="${child}"/>
            <origin xyz="${coords}" rpy="${angles}"/>
        </joint>
    </xacro:macro>

	<xacro:macro name="fixed_joint" params="name parent child coords angles">
        <joint name="${name}" type="fixed">
			<parent link="${parent}"/>
            <child link="${child}"/>
            <origin xyz="${coords}" rpy="${angles}"/>
        </joint>
    </xacro:macro>

	<xacro:property name="leg_radius" value="0.2"/>


	<transm t_name="tran11"  joint="leg1_leg11" m_name="motor11"/>
	<transm t_name="tran22"  joint="leg2_leg22" m_name="motor22"/>
	<transm t_name="tran33"  joint="leg3_leg33" m_name="motor33"/>
	<transm t_name="tran44"  joint="leg4_leg44" m_name="motor44"/>

	<transm t_name="tran111"  joint="leg11_leg111" m_name="motor111"/>
	<transm t_name="tran222"  joint="leg22_leg222" m_name="motor222"/>
	<transm t_name="tran333"  joint="leg33_leg333" m_name="motor333"/>
	<transm t_name="tran444"  joint="leg44_leg444" m_name="motor444"/>

	<transm t_name="tran_camera"  joint="camera_joint" m_name="motor_camera"/>




	<revolute_joint name="camera_joint" parent="leg111" child="camera_link"
				 coords="0.05 0 1" angles="0 0 0" axis="0 1 0" lower="-1" upper="1"/>

	<link name="camera_link">
		<visual>
			<origin xyz="0 0 0" rpy="0 0 0"/>
			<geometry>
				<box size="0.5 0.5 0.5"/>
			</geometry>
			<material name="red"/>
		</visual>

		<inertial>
			<mass value="1e-5"/>
			<origin xyz="0 0 0" rpy="0 0 0"/>
			<inertia ixx="1e-6" ixy="0" ixz="0" iyy="1e-6" iyz="0" izz="1e-6"/>
		</inertial>

	</link>



	<link_cylinder name="leg1"  radius="${leg_radius}" length="2"/>
	<fixed_joint name="base_leg1" parent="base_link" child="leg1"
				 coords="1.3 1.35 3.5" angles="0 2.3 0.8"/>
	<link_cylinder name="leg11" radius = "${leg_radius}" length="2"/>
	<revolute_joint name="leg1_leg11" parent="leg1" child="leg11"
				 coords="-0.8 0 0.9" angles="0 1.5 0" axis="0 1 0" lower="-1" upper="1"/>
	<link_cylinder_collision name="leg111" radius="${leg_radius}" length="4"/>
	<revolute_joint name="leg11_leg111" parent="leg11" child="leg111"
				 coords="-1.3 0 0" angles="0 2 0" axis="0 1 0" lower="-0.3" upper="0.3"/>

	<link_cylinder name="leg2"  radius="${leg_radius}" length="2"/>
	<fixed_joint name="base_leg2" parent="base_link" child="leg2"
				 coords="-1.3 1.35 3.5" angles="0 -2.3 -0.8"/>
	<link_cylinder name="leg22" radius = "${leg_radius}" length="2"/>
	<revolute_joint name="leg2_leg22" parent="leg2" child="leg22"
				 coords="0.8 0 0.9" angles="0 1.5 0" axis="0 1 0" lower="-1" upper="1"/>
	<link_cylinder_collision name="leg222" radius="${leg_radius}" length="4"/>
	<revolute_joint name="leg22_leg222" parent="leg22" child="leg222"
				 coords="-1.3 0 0" angles="0 -2 0" axis="0 1 0" lower="-0.3" upper="0.3"/>

	<link_cylinder name="leg3"  radius="${leg_radius}" length="2"/>
	<fixed_joint name="base_leg3" parent="base_link" child="leg3"
				 coords="-1.3 -1.35 3.5" angles="0 -2.3 0.8"/>
	<link_cylinder name="leg33" radius = "${leg_radius}" length="2"/>
	<revolute_joint name="leg3_leg33" parent="leg3" child="leg33"
				 coords="0.8 0 0.9" angles="0 1.5 0" axis="0 1 0" lower="-1" upper="1"/>
	<link_cylinder_collision name="leg333" radius="${leg_radius}" length="4"/>
	<revolute_joint name="leg33_leg333" parent="leg33" child="leg333"
				 coords="-1.3 0 0" angles="0 -2 0" axis="0 1 0" lower="-0.3" upper="0.3"/>

	<link_cylinder name="leg4"  radius="${leg_radius}" length="2"/>
	<fixed_joint name="base_leg4" parent="base_link" child="leg4"
				 coords="1.3 -1.35 3.5" angles="0 2.3 -0.8"/>
	<link_cylinder name="leg44" radius = "${leg_radius}" length="2"/>
	<revolute_joint name="leg4_leg44" parent="leg4" child="leg44"
				 coords="-0.8 0 0.9" angles="0 4.5 0" axis="0 1 0" lower="-1" upper="1"/>
	<link_cylinder_collision name="leg444" radius="${leg_radius}" length="4"/>
	<revolute_joint name="leg44_leg444" parent="leg44" child="leg444"
				 coords="1.3 0 -0.5" angles="0 2.2 0" axis="0 1 0" lower="-0.3" upper="0.3"/>
	


</robot>